<?xml version="1.0" encoding="UTF-8"?>
<!-- Generated by org.testng.reporters.JUnitReportReporter -->
<testsuite hostname="codebrahma" name="org.collective.testmethods.CollectiveSanityTestCustomer" tests="11" failures="0" timestamp="9 Feb 2016 09:31:08 GMT" time="175.697" errors="9">
  <testcase name="tc005_collective_accessories_Filter_Brand" time="45.694" classname="org.collective.testmethods.CollectiveSanityTestCustomer">
    <error type="java.lang.AssertionError" message="expected [Signed out successfully.] but found []">
      <![CDATA[java.lang.AssertionError: expected [Signed out successfully.] but found []
	at org.testng.Assert.fail(Assert.java:94)
	at org.testng.Assert.failNotEquals(Assert.java:496)
	at org.testng.Assert.assertEquals(Assert.java:125)
	at org.testng.Assert.assertEquals(Assert.java:178)
	at org.testng.Assert.assertEquals(Assert.java:188)
	at org.collective.customer.pageobjects.CollectiveHomePageObjects.verifyLogout(CollectiveHomePageObjects.java:118)
	at org.collective.maincontroller.MainController.checkForLogin(MainController.java:131)
	at sun.reflect.GeneratedMethodAccessor9.invoke(Unknown Source)
	at sun.reflect.DelegatingMethodAccessorImpl.invoke(DelegatingMethodAccessorImpl.java:43)
	at java.lang.reflect.Method.invoke(Method.java:497)
	at org.testng.internal.MethodInvocationHelper.invokeMethod(MethodInvocationHelper.java:85)
	at org.testng.internal.Invoker.invokeConfigurationMethod(Invoker.java:515)
	at org.testng.internal.Invoker.invokeConfigurations(Invoker.java:213)
	at org.testng.internal.Invoker.invokeMethod(Invoker.java:590)
	at org.testng.internal.Invoker.invokeTestMethod(Invoker.java:834)
	at org.testng.internal.Invoker.invokeTestMethods(Invoker.java:1142)
	at org.testng.internal.TestMethodWorker.invokeTestMethods(TestMethodWorker.java:124)
	at org.testng.internal.TestMethodWorker.run(TestMethodWorker.java:108)
	at org.testng.TestRunner.privateRun(TestRunner.java:771)
	at org.testng.TestRunner.run(TestRunner.java:621)
	at org.testng.SuiteRunner.runTest(SuiteRunner.java:357)
	at org.testng.SuiteRunner.runSequentially(SuiteRunner.java:352)
	at org.testng.SuiteRunner.privateRun(SuiteRunner.java:310)
	at org.testng.SuiteRunner.run(SuiteRunner.java:259)
	at org.testng.SuiteRunnerWorker.runSuite(SuiteRunnerWorker.java:52)
	at org.testng.SuiteRunnerWorker.run(SuiteRunnerWorker.java:86)
	at org.testng.TestNG.runSuitesSequentially(TestNG.java:1176)
	at org.testng.TestNG.runSuitesLocally(TestNG.java:1101)
	at org.testng.TestNG.run(TestNG.java:1009)
	at org.testng.remote.RemoteTestNG.run(RemoteTestNG.java:111)
	at org.testng.remote.RemoteTestNG.initAndRun(RemoteTestNG.java:204)
	at org.testng.remote.RemoteTestNG.main(RemoteTestNG.java:175)
]]>
    </error>
  </testcase> <!-- tc005_collective_accessories_Filter_Brand -->
  <testcase name="tc008_collective_orderGreaterThan20000" time="28.703" classname="org.collective.testmethods.CollectiveSanityTestCustomer">
    <error type="java.lang.AssertionError" message="expected [Signed out successfully.] but found []">
      <![CDATA[java.lang.AssertionError: expected [Signed out successfully.] but found []
	at org.testng.Assert.fail(Assert.java:94)
	at org.testng.Assert.failNotEquals(Assert.java:496)
	at org.testng.Assert.assertEquals(Assert.java:125)
	at org.testng.Assert.assertEquals(Assert.java:178)
	at org.testng.Assert.assertEquals(Assert.java:188)
	at org.collective.customer.pageobjects.CollectiveHomePageObjects.verifyLogout(CollectiveHomePageObjects.java:118)
	at org.collective.maincontroller.MainController.checkForLogin(MainController.java:131)
	at sun.reflect.GeneratedMethodAccessor9.invoke(Unknown Source)
	at sun.reflect.DelegatingMethodAccessorImpl.invoke(DelegatingMethodAccessorImpl.java:43)
	at java.lang.reflect.Method.invoke(Method.java:497)
	at org.testng.internal.MethodInvocationHelper.invokeMethod(MethodInvocationHelper.java:85)
	at org.testng.internal.Invoker.invokeConfigurationMethod(Invoker.java:515)
	at org.testng.internal.Invoker.invokeConfigurations(Invoker.java:213)
	at org.testng.internal.Invoker.invokeMethod(Invoker.java:590)
	at org.testng.internal.Invoker.invokeTestMethod(Invoker.java:834)
	at org.testng.internal.Invoker.invokeTestMethods(Invoker.java:1142)
	at org.testng.internal.TestMethodWorker.invokeTestMethods(TestMethodWorker.java:124)
	at org.testng.internal.TestMethodWorker.run(TestMethodWorker.java:108)
	at org.testng.TestRunner.privateRun(TestRunner.java:771)
	at org.testng.TestRunner.run(TestRunner.java:621)
	at org.testng.SuiteRunner.runTest(SuiteRunner.java:357)
	at org.testng.SuiteRunner.runSequentially(SuiteRunner.java:352)
	at org.testng.SuiteRunner.privateRun(SuiteRunner.java:310)
	at org.testng.SuiteRunner.run(SuiteRunner.java:259)
	at org.testng.SuiteRunnerWorker.runSuite(SuiteRunnerWorker.java:52)
	at org.testng.SuiteRunnerWorker.run(SuiteRunnerWorker.java:86)
	at org.testng.TestNG.runSuitesSequentially(TestNG.java:1176)
	at org.testng.TestNG.runSuitesLocally(TestNG.java:1101)
	at org.testng.TestNG.run(TestNG.java:1009)
	at org.testng.remote.RemoteTestNG.run(RemoteTestNG.java:111)
	at org.testng.remote.RemoteTestNG.initAndRun(RemoteTestNG.java:204)
	at org.testng.remote.RemoteTestNG.main(RemoteTestNG.java:175)
]]>
    </error>
  </testcase> <!-- tc008_collective_orderGreaterThan20000 -->
  <testcase name="tc003_collective_blog" time="0.000" classname="org.collective.testmethods.CollectiveSanityTestCustomer">
    <error type="java.lang.AssertionError" message="expected [Signed out successfully.] but found []">
      <![CDATA[java.lang.AssertionError: expected [Signed out successfully.] but found []
	at org.testng.Assert.fail(Assert.java:94)
	at org.testng.Assert.failNotEquals(Assert.java:496)
	at org.testng.Assert.assertEquals(Assert.java:125)
	at org.testng.Assert.assertEquals(Assert.java:178)
	at org.testng.Assert.assertEquals(Assert.java:188)
	at org.collective.customer.pageobjects.CollectiveHomePageObjects.verifyLogout(CollectiveHomePageObjects.java:118)
	at org.collective.maincontroller.MainController.checkForLogin(MainController.java:131)
	at sun.reflect.GeneratedMethodAccessor9.invoke(Unknown Source)
	at sun.reflect.DelegatingMethodAccessorImpl.invoke(DelegatingMethodAccessorImpl.java:43)
	at java.lang.reflect.Method.invoke(Method.java:497)
	at org.testng.internal.MethodInvocationHelper.invokeMethod(MethodInvocationHelper.java:85)
	at org.testng.internal.Invoker.invokeConfigurationMethod(Invoker.java:515)
	at org.testng.internal.Invoker.invokeConfigurations(Invoker.java:213)
	at org.testng.internal.Invoker.invokeMethod(Invoker.java:590)
	at org.testng.internal.Invoker.invokeTestMethod(Invoker.java:834)
	at org.testng.internal.Invoker.invokeTestMethods(Invoker.java:1142)
	at org.testng.internal.TestMethodWorker.invokeTestMethods(TestMethodWorker.java:124)
	at org.testng.internal.TestMethodWorker.run(TestMethodWorker.java:108)
	at org.testng.TestRunner.privateRun(TestRunner.java:771)
	at org.testng.TestRunner.run(TestRunner.java:621)
	at org.testng.SuiteRunner.runTest(SuiteRunner.java:357)
	at org.testng.SuiteRunner.runSequentially(SuiteRunner.java:352)
	at org.testng.SuiteRunner.privateRun(SuiteRunner.java:310)
	at org.testng.SuiteRunner.run(SuiteRunner.java:259)
	at org.testng.SuiteRunnerWorker.runSuite(SuiteRunnerWorker.java:52)
	at org.testng.SuiteRunnerWorker.run(SuiteRunnerWorker.java:86)
	at org.testng.TestNG.runSuitesSequentially(TestNG.java:1176)
	at org.testng.TestNG.runSuitesLocally(TestNG.java:1101)
	at org.testng.TestNG.run(TestNG.java:1009)
	at org.testng.remote.RemoteTestNG.run(RemoteTestNG.java:111)
	at org.testng.remote.RemoteTestNG.initAndRun(RemoteTestNG.java:204)
	at org.testng.remote.RemoteTestNG.main(RemoteTestNG.java:175)
]]>
    </error>
  </testcase> <!-- tc003_collective_blog -->
  <testcase name="tc007_collective_sales" time="0.001" classname="org.collective.testmethods.CollectiveSanityTestCustomer">
    <error type="java.lang.AssertionError" message="expected [Signed out successfully.] but found []">
      <![CDATA[java.lang.AssertionError: expected [Signed out successfully.] but found []
	at org.testng.Assert.fail(Assert.java:94)
	at org.testng.Assert.failNotEquals(Assert.java:496)
	at org.testng.Assert.assertEquals(Assert.java:125)
	at org.testng.Assert.assertEquals(Assert.java:178)
	at org.testng.Assert.assertEquals(Assert.java:188)
	at org.collective.customer.pageobjects.CollectiveHomePageObjects.verifyLogout(CollectiveHomePageObjects.java:118)
	at org.collective.maincontroller.MainController.checkForLogin(MainController.java:131)
	at sun.reflect.GeneratedMethodAccessor9.invoke(Unknown Source)
	at sun.reflect.DelegatingMethodAccessorImpl.invoke(DelegatingMethodAccessorImpl.java:43)
	at java.lang.reflect.Method.invoke(Method.java:497)
	at org.testng.internal.MethodInvocationHelper.invokeMethod(MethodInvocationHelper.java:85)
	at org.testng.internal.Invoker.invokeConfigurationMethod(Invoker.java:515)
	at org.testng.internal.Invoker.invokeConfigurations(Invoker.java:213)
	at org.testng.internal.Invoker.invokeMethod(Invoker.java:590)
	at org.testng.internal.Invoker.invokeTestMethod(Invoker.java:834)
	at org.testng.internal.Invoker.invokeTestMethods(Invoker.java:1142)
	at org.testng.internal.TestMethodWorker.invokeTestMethods(TestMethodWorker.java:124)
	at org.testng.internal.TestMethodWorker.run(TestMethodWorker.java:108)
	at org.testng.TestRunner.privateRun(TestRunner.java:771)
	at org.testng.TestRunner.run(TestRunner.java:621)
	at org.testng.SuiteRunner.runTest(SuiteRunner.java:357)
	at org.testng.SuiteRunner.runSequentially(SuiteRunner.java:352)
	at org.testng.SuiteRunner.privateRun(SuiteRunner.java:310)
	at org.testng.SuiteRunner.run(SuiteRunner.java:259)
	at org.testng.SuiteRunnerWorker.runSuite(SuiteRunnerWorker.java:52)
	at org.testng.SuiteRunnerWorker.run(SuiteRunnerWorker.java:86)
	at org.testng.TestNG.runSuitesSequentially(TestNG.java:1176)
	at org.testng.TestNG.runSuitesLocally(TestNG.java:1101)
	at org.testng.TestNG.run(TestNG.java:1009)
	at org.testng.remote.RemoteTestNG.run(RemoteTestNG.java:111)
	at org.testng.remote.RemoteTestNG.initAndRun(RemoteTestNG.java:204)
	at org.testng.remote.RemoteTestNG.main(RemoteTestNG.java:175)
]]>
    </error>
  </testcase> <!-- tc007_collective_sales -->
  <testcase name="tc009_collective_orderLessOrEqualThan20000" time="0.002" classname="org.collective.testmethods.CollectiveSanityTestCustomer">
    <error type="java.lang.AssertionError" message="expected [Signed out successfully.] but found []">
      <![CDATA[java.lang.AssertionError: expected [Signed out successfully.] but found []
	at org.testng.Assert.fail(Assert.java:94)
	at org.testng.Assert.failNotEquals(Assert.java:496)
	at org.testng.Assert.assertEquals(Assert.java:125)
	at org.testng.Assert.assertEquals(Assert.java:178)
	at org.testng.Assert.assertEquals(Assert.java:188)
	at org.collective.customer.pageobjects.CollectiveHomePageObjects.verifyLogout(CollectiveHomePageObjects.java:118)
	at org.collective.maincontroller.MainController.checkForLogin(MainController.java:131)
	at sun.reflect.GeneratedMethodAccessor9.invoke(Unknown Source)
	at sun.reflect.DelegatingMethodAccessorImpl.invoke(DelegatingMethodAccessorImpl.java:43)
	at java.lang.reflect.Method.invoke(Method.java:497)
	at org.testng.internal.MethodInvocationHelper.invokeMethod(MethodInvocationHelper.java:85)
	at org.testng.internal.Invoker.invokeConfigurationMethod(Invoker.java:515)
	at org.testng.internal.Invoker.invokeConfigurations(Invoker.java:213)
	at org.testng.internal.Invoker.invokeMethod(Invoker.java:590)
	at org.testng.internal.Invoker.invokeTestMethod(Invoker.java:834)
	at org.testng.internal.Invoker.invokeTestMethods(Invoker.java:1142)
	at org.testng.internal.TestMethodWorker.invokeTestMethods(TestMethodWorker.java:124)
	at org.testng.internal.TestMethodWorker.run(TestMethodWorker.java:108)
	at org.testng.TestRunner.privateRun(TestRunner.java:771)
	at org.testng.TestRunner.run(TestRunner.java:621)
	at org.testng.SuiteRunner.runTest(SuiteRunner.java:357)
	at org.testng.SuiteRunner.runSequentially(SuiteRunner.java:352)
	at org.testng.SuiteRunner.privateRun(SuiteRunner.java:310)
	at org.testng.SuiteRunner.run(SuiteRunner.java:259)
	at org.testng.SuiteRunnerWorker.runSuite(SuiteRunnerWorker.java:52)
	at org.testng.SuiteRunnerWorker.run(SuiteRunnerWorker.java:86)
	at org.testng.TestNG.runSuitesSequentially(TestNG.java:1176)
	at org.testng.TestNG.runSuitesLocally(TestNG.java:1101)
	at org.testng.TestNG.run(TestNG.java:1009)
	at org.testng.remote.RemoteTestNG.run(RemoteTestNG.java:111)
	at org.testng.remote.RemoteTestNG.initAndRun(RemoteTestNG.java:204)
	at org.testng.remote.RemoteTestNG.main(RemoteTestNG.java:175)
]]>
    </error>
  </testcase> <!-- tc009_collective_orderLessOrEqualThan20000 -->
  <testcase name="tc011_collective_placeorder_OrderCancellation" time="0.001" classname="org.collective.testmethods.CollectiveSanityTestCustomer">
    <error type="java.lang.AssertionError" message="expected [Signed out successfully.] but found []">
      <![CDATA[java.lang.AssertionError: expected [Signed out successfully.] but found []
	at org.testng.Assert.fail(Assert.java:94)
	at org.testng.Assert.failNotEquals(Assert.java:496)
	at org.testng.Assert.assertEquals(Assert.java:125)
	at org.testng.Assert.assertEquals(Assert.java:178)
	at org.testng.Assert.assertEquals(Assert.java:188)
	at org.collective.customer.pageobjects.CollectiveHomePageObjects.verifyLogout(CollectiveHomePageObjects.java:118)
	at org.collective.maincontroller.MainController.checkForLogin(MainController.java:131)
	at sun.reflect.GeneratedMethodAccessor9.invoke(Unknown Source)
	at sun.reflect.DelegatingMethodAccessorImpl.invoke(DelegatingMethodAccessorImpl.java:43)
	at java.lang.reflect.Method.invoke(Method.java:497)
	at org.testng.internal.MethodInvocationHelper.invokeMethod(MethodInvocationHelper.java:85)
	at org.testng.internal.Invoker.invokeConfigurationMethod(Invoker.java:515)
	at org.testng.internal.Invoker.invokeConfigurations(Invoker.java:213)
	at org.testng.internal.Invoker.invokeMethod(Invoker.java:590)
	at org.testng.internal.Invoker.invokeTestMethod(Invoker.java:834)
	at org.testng.internal.Invoker.invokeTestMethods(Invoker.java:1142)
	at org.testng.internal.TestMethodWorker.invokeTestMethods(TestMethodWorker.java:124)
	at org.testng.internal.TestMethodWorker.run(TestMethodWorker.java:108)
	at org.testng.TestRunner.privateRun(TestRunner.java:771)
	at org.testng.TestRunner.run(TestRunner.java:621)
	at org.testng.SuiteRunner.runTest(SuiteRunner.java:357)
	at org.testng.SuiteRunner.runSequentially(SuiteRunner.java:352)
	at org.testng.SuiteRunner.privateRun(SuiteRunner.java:310)
	at org.testng.SuiteRunner.run(SuiteRunner.java:259)
	at org.testng.SuiteRunnerWorker.runSuite(SuiteRunnerWorker.java:52)
	at org.testng.SuiteRunnerWorker.run(SuiteRunnerWorker.java:86)
	at org.testng.TestNG.runSuitesSequentially(TestNG.java:1176)
	at org.testng.TestNG.runSuitesLocally(TestNG.java:1101)
	at org.testng.TestNG.run(TestNG.java:1009)
	at org.testng.remote.RemoteTestNG.run(RemoteTestNG.java:111)
	at org.testng.remote.RemoteTestNG.initAndRun(RemoteTestNG.java:204)
	at org.testng.remote.RemoteTestNG.main(RemoteTestNG.java:175)
]]>
    </error>
  </testcase> <!-- tc011_collective_placeorder_OrderCancellation -->
  <testcase name="tc004_collective_accessories" time="0.001" classname="org.collective.testmethods.CollectiveSanityTestCustomer">
    <error type="java.lang.AssertionError" message="expected [Signed out successfully.] but found []">
      <![CDATA[java.lang.AssertionError: expected [Signed out successfully.] but found []
	at org.testng.Assert.fail(Assert.java:94)
	at org.testng.Assert.failNotEquals(Assert.java:496)
	at org.testng.Assert.assertEquals(Assert.java:125)
	at org.testng.Assert.assertEquals(Assert.java:178)
	at org.testng.Assert.assertEquals(Assert.java:188)
	at org.collective.customer.pageobjects.CollectiveHomePageObjects.verifyLogout(CollectiveHomePageObjects.java:118)
	at org.collective.maincontroller.MainController.checkForLogin(MainController.java:131)
	at sun.reflect.GeneratedMethodAccessor9.invoke(Unknown Source)
	at sun.reflect.DelegatingMethodAccessorImpl.invoke(DelegatingMethodAccessorImpl.java:43)
	at java.lang.reflect.Method.invoke(Method.java:497)
	at org.testng.internal.MethodInvocationHelper.invokeMethod(MethodInvocationHelper.java:85)
	at org.testng.internal.Invoker.invokeConfigurationMethod(Invoker.java:515)
	at org.testng.internal.Invoker.invokeConfigurations(Invoker.java:213)
	at org.testng.internal.Invoker.invokeMethod(Invoker.java:590)
	at org.testng.internal.Invoker.invokeTestMethod(Invoker.java:834)
	at org.testng.internal.Invoker.invokeTestMethods(Invoker.java:1142)
	at org.testng.internal.TestMethodWorker.invokeTestMethods(TestMethodWorker.java:124)
	at org.testng.internal.TestMethodWorker.run(TestMethodWorker.java:108)
	at org.testng.TestRunner.privateRun(TestRunner.java:771)
	at org.testng.TestRunner.run(TestRunner.java:621)
	at org.testng.SuiteRunner.runTest(SuiteRunner.java:357)
	at org.testng.SuiteRunner.runSequentially(SuiteRunner.java:352)
	at org.testng.SuiteRunner.privateRun(SuiteRunner.java:310)
	at org.testng.SuiteRunner.run(SuiteRunner.java:259)
	at org.testng.SuiteRunnerWorker.runSuite(SuiteRunnerWorker.java:52)
	at org.testng.SuiteRunnerWorker.run(SuiteRunnerWorker.java:86)
	at org.testng.TestNG.runSuitesSequentially(TestNG.java:1176)
	at org.testng.TestNG.runSuitesLocally(TestNG.java:1101)
	at org.testng.TestNG.run(TestNG.java:1009)
	at org.testng.remote.RemoteTestNG.run(RemoteTestNG.java:111)
	at org.testng.remote.RemoteTestNG.initAndRun(RemoteTestNG.java:204)
	at org.testng.remote.RemoteTestNG.main(RemoteTestNG.java:175)
]]>
    </error>
  </testcase> <!-- tc004_collective_accessories -->
  <testcase name="tc006_collective_pagination" time="0.001" classname="org.collective.testmethods.CollectiveSanityTestCustomer">
    <error type="java.lang.AssertionError" message="expected [Signed out successfully.] but found []">
      <![CDATA[java.lang.AssertionError: expected [Signed out successfully.] but found []
	at org.testng.Assert.fail(Assert.java:94)
	at org.testng.Assert.failNotEquals(Assert.java:496)
	at org.testng.Assert.assertEquals(Assert.java:125)
	at org.testng.Assert.assertEquals(Assert.java:178)
	at org.testng.Assert.assertEquals(Assert.java:188)
	at org.collective.customer.pageobjects.CollectiveHomePageObjects.verifyLogout(CollectiveHomePageObjects.java:118)
	at org.collective.maincontroller.MainController.checkForLogin(MainController.java:131)
	at sun.reflect.GeneratedMethodAccessor9.invoke(Unknown Source)
	at sun.reflect.DelegatingMethodAccessorImpl.invoke(DelegatingMethodAccessorImpl.java:43)
	at java.lang.reflect.Method.invoke(Method.java:497)
	at org.testng.internal.MethodInvocationHelper.invokeMethod(MethodInvocationHelper.java:85)
	at org.testng.internal.Invoker.invokeConfigurationMethod(Invoker.java:515)
	at org.testng.internal.Invoker.invokeConfigurations(Invoker.java:213)
	at org.testng.internal.Invoker.invokeMethod(Invoker.java:590)
	at org.testng.internal.Invoker.invokeTestMethod(Invoker.java:834)
	at org.testng.internal.Invoker.invokeTestMethods(Invoker.java:1142)
	at org.testng.internal.TestMethodWorker.invokeTestMethods(TestMethodWorker.java:124)
	at org.testng.internal.TestMethodWorker.run(TestMethodWorker.java:108)
	at org.testng.TestRunner.privateRun(TestRunner.java:771)
	at org.testng.TestRunner.run(TestRunner.java:621)
	at org.testng.SuiteRunner.runTest(SuiteRunner.java:357)
	at org.testng.SuiteRunner.runSequentially(SuiteRunner.java:352)
	at org.testng.SuiteRunner.privateRun(SuiteRunner.java:310)
	at org.testng.SuiteRunner.run(SuiteRunner.java:259)
	at org.testng.SuiteRunnerWorker.runSuite(SuiteRunnerWorker.java:52)
	at org.testng.SuiteRunnerWorker.run(SuiteRunnerWorker.java:86)
	at org.testng.TestNG.runSuitesSequentially(TestNG.java:1176)
	at org.testng.TestNG.runSuitesLocally(TestNG.java:1101)
	at org.testng.TestNG.run(TestNG.java:1009)
	at org.testng.remote.RemoteTestNG.run(RemoteTestNG.java:111)
	at org.testng.remote.RemoteTestNG.initAndRun(RemoteTestNG.java:204)
	at org.testng.remote.RemoteTestNG.main(RemoteTestNG.java:175)
]]>
    </error>
  </testcase> <!-- tc006_collective_pagination -->
  <testcase name="tc010_collective_orderPlacement" time="0.000" classname="org.collective.testmethods.CollectiveSanityTestCustomer">
    <error type="java.lang.AssertionError" message="expected [Signed out successfully.] but found []">
      <![CDATA[java.lang.AssertionError: expected [Signed out successfully.] but found []
	at org.testng.Assert.fail(Assert.java:94)
	at org.testng.Assert.failNotEquals(Assert.java:496)
	at org.testng.Assert.assertEquals(Assert.java:125)
	at org.testng.Assert.assertEquals(Assert.java:178)
	at org.testng.Assert.assertEquals(Assert.java:188)
	at org.collective.customer.pageobjects.CollectiveHomePageObjects.verifyLogout(CollectiveHomePageObjects.java:118)
	at org.collective.maincontroller.MainController.checkForLogin(MainController.java:131)
	at sun.reflect.GeneratedMethodAccessor9.invoke(Unknown Source)
	at sun.reflect.DelegatingMethodAccessorImpl.invoke(DelegatingMethodAccessorImpl.java:43)
	at java.lang.reflect.Method.invoke(Method.java:497)
	at org.testng.internal.MethodInvocationHelper.invokeMethod(MethodInvocationHelper.java:85)
	at org.testng.internal.Invoker.invokeConfigurationMethod(Invoker.java:515)
	at org.testng.internal.Invoker.invokeConfigurations(Invoker.java:213)
	at org.testng.internal.Invoker.invokeMethod(Invoker.java:590)
	at org.testng.internal.Invoker.invokeTestMethod(Invoker.java:834)
	at org.testng.internal.Invoker.invokeTestMethods(Invoker.java:1142)
	at org.testng.internal.TestMethodWorker.invokeTestMethods(TestMethodWorker.java:124)
	at org.testng.internal.TestMethodWorker.run(TestMethodWorker.java:108)
	at org.testng.TestRunner.privateRun(TestRunner.java:771)
	at org.testng.TestRunner.run(TestRunner.java:621)
	at org.testng.SuiteRunner.runTest(SuiteRunner.java:357)
	at org.testng.SuiteRunner.runSequentially(SuiteRunner.java:352)
	at org.testng.SuiteRunner.privateRun(SuiteRunner.java:310)
	at org.testng.SuiteRunner.run(SuiteRunner.java:259)
	at org.testng.SuiteRunnerWorker.runSuite(SuiteRunnerWorker.java:52)
	at org.testng.SuiteRunnerWorker.run(SuiteRunnerWorker.java:86)
	at org.testng.TestNG.runSuitesSequentially(TestNG.java:1176)
	at org.testng.TestNG.runSuitesLocally(TestNG.java:1101)
	at org.testng.TestNG.run(TestNG.java:1009)
	at org.testng.remote.RemoteTestNG.run(RemoteTestNG.java:111)
	at org.testng.remote.RemoteTestNG.initAndRun(RemoteTestNG.java:204)
	at org.testng.remote.RemoteTestNG.main(RemoteTestNG.java:175)
]]>
    </error>
  </testcase> <!-- tc010_collective_orderPlacement -->
  <testcase name="tc002_collective_login" time="38.378" classname="org.collective.testmethods.CollectiveSanityTestCustomer"/>
  <testcase name="tc001_collective_signup" time="62.916" classname="org.collective.testmethods.CollectiveSanityTestCustomer"/>
</testsuite> <!-- org.collective.testmethods.CollectiveSanityTestCustomer -->
